[2017-01-12 02:14:01,355][app.getName][ERROR] 无法连接https://www.zhanqi.tv/34234324324
Traceback (most recent call last):
  File "/home/jack/pythoncoding/easySee/app/getName.py", line 81, in zhanqi
    self.name = re.findall(pattern, r)[0]
IndexError: list index out of range
[2017-01-12 15:22:45,233][app.getName][ERROR] 无法连接http://www.quanmin.tv/json/rooms/234124324324/noinfo4.json
Traceback (most recent call last):
  File "/home/jack/pythoncoding/easySee/app/getName.py", line 64, in quanmin
    r = s.get(url, proxies=random.choice(PROXIES)).json()
NameError: global name 's' is not defined
[2017-01-12 15:22:54,446][app.getName][ERROR] 无法连接http://www.quanmin.tv/json/rooms/90888dopa/noinfo4.json
Traceback (most recent call last):
  File "/home/jack/pythoncoding/easySee/app/getName.py", line 64, in quanmin
    r = s.get(url, proxies=random.choice(PROXIES)).json()
NameError: global name 's' is not defined
[2017-01-12 15:23:07,883][app.getName][ERROR] 无法连接http://www.huya.com/90888dopa
Traceback (most recent call last):
  File "/home/jack/pythoncoding/easySee/app/getName.py", line 73, in huya
    r = s.get(url, proxies=random.choice(PROXIES)).text
NameError: global name 's' is not defined
[2017-01-12 15:23:21,820][app.getName][ERROR] 无法连接http://star.longzhu.com/dongzhu
Traceback (most recent call last):
  File "/home/jack/pythoncoding/easySee/app/getName.py", line 54, in longzhu
    r = s.get(url, proxies=random.choice(PROXIES)).text
NameError: global name 's' is not defined
[2017-01-12 15:23:31,613][app.getName][ERROR] 无法连接http://star.longzhu.com/dongzhu
Traceback (most recent call last):
  File "/home/jack/pythoncoding/easySee/app/getName.py", line 54, in longzhu
    r = s.get(url, proxies=random.choice(PROXIES)).text
NameError: global name 's' is not defined
[2017-01-12 15:25:31,985][app.getName][ERROR] 无法连接http://www.quanmin.tv/json/rooms/4324324234324/noinfo4.json
Traceback (most recent call last):
  File "/home/jack/pythoncoding/easySee/app/getName.py", line 63, in quanmin
    r = s.get(url, proxies=random.choice(PROXIES)).json()
NameError: global name 's' is not defined
[2017-01-12 15:27:22,477][app.getName][ERROR] 无法连接http://star.longzhu.com/dongzhu
Traceback (most recent call last):
  File "/home/jack/pythoncoding/easySee/app/getName.py", line 53, in longzhu
    r = s.get(url, proxies=random.choice(PROXIES)).text
NameError: global name 's' is not defined
[2017-01-12 23:20:04,974][app.getName][ERROR] 无法连接http://www.panda.tv/6666
Traceback (most recent call last):
  File "/home/jack/pythoncoding/easySee/app/getName.py", line 44, in xiongmao
    r = self.s.get(url, proxies=random.choice(PROXIES)).text
  File "/home/jack/easyenv/local/lib/python2.7/site-packages/requests/sessions.py", line 501, in get
    return self.request('GET', url, **kwargs)
  File "/home/jack/easyenv/local/lib/python2.7/site-packages/requests/sessions.py", line 488, in request
    resp = self.send(prep, **send_kwargs)
  File "/home/jack/easyenv/local/lib/python2.7/site-packages/requests/sessions.py", line 609, in send
    r = adapter.send(request, **kwargs)
  File "/home/jack/easyenv/local/lib/python2.7/site-packages/requests/adapters.py", line 487, in send
    raise ConnectionError(e, request=request)
ConnectionError: HTTPConnectionPool(host='www.panda.tv', port=80): Max retries exceeded with url: /6666 (Caused by NewConnectionError('<requests.packages.urllib3.connection.HTTPConnection object at 0x7f7cd88a8510>: Failed to establish a new connection: [Errno -3] Temporary failure in name resolution',))
[2017-01-12 23:20:10,392][app.getName][ERROR] 无法连接http://www.panda.tv/6666
Traceback (most recent call last):
  File "/home/jack/pythoncoding/easySee/app/getName.py", line 44, in xiongmao
    r = self.s.get(url, proxies=random.choice(PROXIES)).text
  File "/home/jack/easyenv/local/lib/python2.7/site-packages/requests/sessions.py", line 501, in get
    return self.request('GET', url, **kwargs)
  File "/home/jack/easyenv/local/lib/python2.7/site-packages/requests/sessions.py", line 488, in request
    resp = self.send(prep, **send_kwargs)
  File "/home/jack/easyenv/local/lib/python2.7/site-packages/requests/sessions.py", line 609, in send
    r = adapter.send(request, **kwargs)
  File "/home/jack/easyenv/local/lib/python2.7/site-packages/requests/adapters.py", line 487, in send
    raise ConnectionError(e, request=request)
ConnectionError: HTTPConnectionPool(host='www.panda.tv', port=80): Max retries exceeded with url: /6666 (Caused by NewConnectionError('<requests.packages.urllib3.connection.HTTPConnection object at 0x7f7cd6746dd0>: Failed to establish a new connection: [Errno -3] Temporary failure in name resolution',))
[2017-01-12 23:20:16,074][app.getName][ERROR] 无法连接http://www.panda.tv/6666
Traceback (most recent call last):
  File "/home/jack/pythoncoding/easySee/app/getName.py", line 44, in xiongmao
    r = self.s.get(url, proxies=random.choice(PROXIES)).text
  File "/home/jack/easyenv/local/lib/python2.7/site-packages/requests/sessions.py", line 501, in get
    return self.request('GET', url, **kwargs)
  File "/home/jack/easyenv/local/lib/python2.7/site-packages/requests/sessions.py", line 488, in request
    resp = self.send(prep, **send_kwargs)
  File "/home/jack/easyenv/local/lib/python2.7/site-packages/requests/sessions.py", line 609, in send
    r = adapter.send(request, **kwargs)
  File "/home/jack/easyenv/local/lib/python2.7/site-packages/requests/adapters.py", line 487, in send
    raise ConnectionError(e, request=request)
ConnectionError: HTTPConnectionPool(host='www.panda.tv', port=80): Max retries exceeded with url: /6666 (Caused by NewConnectionError('<requests.packages.urllib3.connection.HTTPConnection object at 0x7f7cd6754290>: Failed to establish a new connection: [Errno -3] Temporary failure in name resolution',))
[2017-01-12 23:23:00,008][app.getName][ERROR] 无法连接http://www.panda.tv/6666
Traceback (most recent call last):
  File "/home/jack/pythoncoding/easySee/app/getName.py", line 44, in xiongmao
    r = self.s.get(url, proxies=random.choice(PROXIES)).text
  File "/home/jack/easyenv/local/lib/python2.7/site-packages/requests/sessions.py", line 501, in get
    return self.request('GET', url, **kwargs)
  File "/home/jack/easyenv/local/lib/python2.7/site-packages/requests/sessions.py", line 488, in request
    resp = self.send(prep, **send_kwargs)
  File "/home/jack/easyenv/local/lib/python2.7/site-packages/requests/sessions.py", line 609, in send
    r = adapter.send(request, **kwargs)
  File "/home/jack/easyenv/local/lib/python2.7/site-packages/requests/adapters.py", line 487, in send
    raise ConnectionError(e, request=request)
ConnectionError: HTTPConnectionPool(host='www.panda.tv', port=80): Max retries exceeded with url: /6666 (Caused by NewConnectionError('<requests.packages.urllib3.connection.HTTPConnection object at 0x7f7cd6746c50>: Failed to establish a new connection: [Errno -3] Temporary failure in name resolution',))
[2017-01-12 23:25:11,194][app.getName][ERROR] 无法连接http://www.panda.tv/6666
Traceback (most recent call last):
  File "/home/jack/pythoncoding/easySee/app/getName.py", line 44, in xiongmao
    r = self.s.get(url, proxies=random.choice(PROXIES)).text
  File "/home/jack/easyenv/local/lib/python2.7/site-packages/requests/sessions.py", line 501, in get
    return self.request('GET', url, **kwargs)
  File "/home/jack/easyenv/local/lib/python2.7/site-packages/requests/sessions.py", line 488, in request
    resp = self.send(prep, **send_kwargs)
  File "/home/jack/easyenv/local/lib/python2.7/site-packages/requests/sessions.py", line 609, in send
    r = adapter.send(request, **kwargs)
  File "/home/jack/easyenv/local/lib/python2.7/site-packages/requests/adapters.py", line 487, in send
    raise ConnectionError(e, request=request)
ConnectionError: HTTPConnectionPool(host='www.panda.tv', port=80): Max retries exceeded with url: /6666 (Caused by NewConnectionError('<requests.packages.urllib3.connection.HTTPConnection object at 0x7f6e9d1d9410>: Failed to establish a new connection: [Errno -3] Temporary failure in name resolution',))
[2017-01-12 23:26:13,999][app.getName][ERROR] 无法连接http://www.panda.tv/6666
Traceback (most recent call last):
  File "/home/jack/pythoncoding/easySee/app/getName.py", line 45, in xiongmao
    r = self.s.get(url, proxies=random.choice(PROXIES)).text
  File "/home/jack/easyenv/local/lib/python2.7/site-packages/requests/sessions.py", line 501, in get
    return self.request('GET', url, **kwargs)
  File "/home/jack/easyenv/local/lib/python2.7/site-packages/requests/sessions.py", line 488, in request
    resp = self.send(prep, **send_kwargs)
  File "/home/jack/easyenv/local/lib/python2.7/site-packages/requests/sessions.py", line 609, in send
    r = adapter.send(request, **kwargs)
  File "/home/jack/easyenv/local/lib/python2.7/site-packages/requests/adapters.py", line 487, in send
    raise ConnectionError(e, request=request)
ConnectionError: HTTPConnectionPool(host='www.panda.tv', port=80): Max retries exceeded with url: /6666 (Caused by NewConnectionError('<requests.packages.urllib3.connection.HTTPConnection object at 0x7ff32946d890>: Failed to establish a new connection: [Errno -3] Temporary failure in name resolution',))
